<?xml version="1.0" ?>
<robot name="SetGuai" xmlns:xacro="http://ros.org/wiki/xacro">
  <!--xacro:include filename="$(find description)/urdf/common_properties.xacro"/-->
  <xacro:include filename="$(find description)/urdf/setguai.gazebo.xacro"/>
  <xacro:include filename="$(find description)/urdf/setguai_transmision.xacro"/>
  
  <xacro:property name="masa1" value="1" />
  <xacro:property name="masa2" value="2" />

  <link name="base_footprint"/>

  <joint name="base_joint" type="fixed">
    <parent link="base_footprint"/>
    <child link="base_link"/>
    <origin xyz="0.0 0.0 0.033" rpy="0 0 0"/> <!-- altura de radio -->
  </joint>

  <link name="base_link">
    <visual>  <!-- BASE -->
      <origin xyz="0.0 0.0 0.0" rpy="0 0 0"/>
      <geometry>
        <box size="0.02 0.14 0.01"/>
      </geometry>
      <material name="light_black"/>
    </visual>

    <collision>  <!-- BASE -->
      <origin xyz="0.0 0.0 0.0" rpy="0 0 0"/>
      <geometry>
        <box size="0.02 0.14 0.01"/>
      </geometry>
    </collision>

    <inertial>
      <origin xyz="0.0 0.0 0.0" rpy="0 0 0"/>
      <mass value= "${masa1}"/>
      <inertia ixx="${masa1 / 12.0 * ((0.14 * 0.14) + (0.01 * 0.01))}" ixy="0" ixz="0"
               iyy="${masa1 / 12.0 * ((0.02 * 0.02) + (0.01 * 0.01))}" iyz="0"
               izz="${masa1 / 12.0 * ((0.14 * 0.14) + (0.02 * 0.02))}" />
    </inertial>
  </link>

  <joint name="wheel_left_joint" type="continuous">
    <parent link="base_link"/>
    <child link="wheel_left_link"/>
    <origin xyz="0.0 0.08 0.00" rpy="-1.57 0 0"/>
    <axis xyz="0 0 1"/>
  </joint>

  <link name="wheel_left_link">
    <visual>
      <origin xyz="0 0 0" rpy="0 0 0"/>
      <geometry>
        <box size="0.066 0.066 0.015"/>
      </geometry>
      <material name="dark"/>
    </visual>

    <collision>
      <origin xyz="0 0 0" rpy="0 0 0"/>
      <geometry>
        <box size="0.066 0.066 0.015"/>
      </geometry>
    </collision>

    <inertial>
      <origin xyz="0 0 0" />
      <mass value="50" />
      <inertia ixx="0.001" ixy="0" ixz="0"
               iyy="0.001" iyz="0"
               izz="0.002" />
      </inertial>
  </link>

  <joint name="wheel_right_joint" type="continuous">
    <parent link="base_link"/>
    <child link="wheel_right_link"/>
    <origin xyz="0.0 -0.080 0.00" rpy="-1.57 0 0"/>
    <axis xyz="0 0 1"/>
  </joint>

  <link name="wheel_right_link">
    <visual>
      <origin xyz="0 0 0" rpy="0 0 0"/>
      <geometry>
        <box size="0.066 0.066 0.015"/>
      </geometry>
      <material name="dark"/>
    </visual>

    <collision>
      <origin xyz="0 0 0" rpy="0 0 0"/>
      <geometry>
        <box size="0.066 0.066 0.015"/>
      </geometry>
    </collision>

    <inertial>
      <origin xyz="0 0 0" />
      <mass value="50" />
      <inertia ixx="0.001" ixy="0" ixz="0"
               iyy="0.001" iyz="0"
               izz="0.002" />
      </inertial>
  </link>

  <joint name="pendulo_joint" type="fixed">
    <parent link="base_link"/>
    <child link="pendulo_link"/>
    <origin xyz="0.0 0.0 0.105" rpy="0 0 0"/>
  </joint>

  <link name="pendulo_link">
    <visual>
      <origin xyz="0.0 0.0 0.0" rpy="0 0 0"/>
      <geometry>
        <box size="0.01 0.02 0.2"/>
      </geometry>
      <material name="blue"/>
    </visual>
    <collision>
      <origin xyz="0.0 0.0 0.0" rpy="0 0 0"/>
      <geometry>
        <box size="0.01 0.02 0.2"/>
      </geometry>
    </collision>

    <inertial>
      <origin xyz="0 0 0" />
      <mass value="${masa2}" />
      <inertia ixx="${masa2 / 12.0 * ((0.02 * 0.02) + (0.2 * 0.2))}" ixy="0" ixz="0"
               iyy="${masa2 / 12.0 * ((0.01 * 0.01) + (0.2 * 0.2))}" iyz="0"
               izz="${masa2 / 12.0 * ((0.02 * 0.02) + (0.01 * 0.01))}" />
    </inertial>
  </link>

  <joint name="imu_joint" type="fixed">
    <parent link="base_link"/>
    <child link="imu_link"/>
    <origin xyz="0.0 0.0 0.195" rpy="0 0 0"/>
  </joint>

  <link name="imu_link">
      <visual name="visual">
        <origin xyz="0.01 0.0 0.0" rpy="0 0 0"/> 
        <geometry>
          <box size="0.01 0.01 0.01"/>
        </geometry>
        <material name="blue"/>
      </visual>
      <collision name="collision">
        <origin xyz="0.01 0.0 0.0" rpy="0 0 0"/> 
        <geometry>
          <box size="0.01 0.01 0.01"/>
        </geometry>
      </collision>
      <inertial>
        <inertia ixx="0.1" ixy="0" ixz="0"
               iyy="0.1" iyz="0"
               izz="0.1" />
        <mass value="1" />
      </inertial>
 </link>


</robot>
